<robot name="Mechatronics Arm">
    <material name="cyan1">
        <color rgba="0 0.9 0.9 1.0"/>
    </material>
    <material name="cyan2">
        <color rgba="0 0.4 0.4 1.0"/>
    </material>
    <material name="black">
        <color rgba="0.1 0.1 0.1 1.0"/>
    </material>
    <material name="white">
        <color rgba="0.9 0.9 0.9 1.0"/>
    </material>
    <material name="grey">
        <color rgba="0.3 0.3 0.3 1.0"/>
    </material>


    <link name="world_base_link">
        <visual>
            <origin xyz="0 0 .028" rpy="0 0 0"/>
            <geometry>
                <cylinder length="0.056" radius="0.04"/>
            </geometry>
            <material name="cyan1"/>
        </visual>
    </link>
    <joint name="base" type="fixed">
        <parent link="world_base_link"/>
        <child link="base_waist_link"/>
        <origin xyz="0 0 .0560" rpy="0 0 0"/>
        <axis xyz="0 0 1"/>
    </joint>
    <link name="base_waist_link">
        <visual>
            <origin xyz="0 0 0" rpy="0 0 0"/>
            <geometry>
                <cylinder length="0.01" radius="0.035"/>
            </geometry>
            <material name="white"/>
        </visual>
    </link>
    <joint name="waist" type="revolute">
        <parent link="base_waist_link"/>
        <child link="waist_shoulder_link"/>
        <origin xyz="0 0 .04293" rpy="0 0 1.57"/>
        <axis xyz="0 0 1"/>
        <limit lower="-1.57" upper="1.57" effort="1000.0" velocity="0.5"/>
    </joint>
    <link name="waist_shoulder_link">
        <visual>
            <origin xyz="0 0 -.021" rpy="0 0 0"/>
            <geometry>
                <box size="0.030 0.015 0.042"/>
            </geometry>
            <material name="white"/>
        </visual>
        <visual>
            <origin xyz="0 0 0" rpy="1.571 0 0"/>
            <geometry>
                <cylinder length="0.02" radius="0.015"/>
            </geometry>
            <material name="white"/>
        </visual>
    </link>
    <joint name="shoulder" type="revolute">
        <parent link="waist_shoulder_link"/>
        <child link="shoulder_elbow_link"/>
        <origin xyz="0 0 0" rpy="0 2.87979 0"/>
        <axis xyz="0 -1 0"/>
        <limit lower="0" upper="2.87979" effort="1000.0" velocity="0.5"/>
    </joint>
    <link name="shoulder_elbow_link">
        <visual>
            <origin xyz="0 0 .06" rpy="0 0 0"/>
            <geometry>
                <box size="0.030 0.015 0.120"/>
            </geometry>
            <material name="cyan2"/>
        </visual>
        <visual>
            <origin xyz="0 0 0.120" rpy="1.571 0 0"/>
            <geometry>
                <cylinder length="0.02" radius="0.015"/>
            </geometry>
            <material name="cyan2"/>
        </visual>
    </link>
    <joint name="elbow" type="revolute">
        <parent link="shoulder_elbow_link"/>
        <child link="elbow_wrist_roll_link"/>
        <origin xyz="0 0 .11865" rpy="0 1.57 0"/>
        <axis xyz="0 1 0"/>
        <limit lower="0" upper="1.0472" effort="1000.0" velocity="0.5"/>
    </joint>
    <link name="elbow_wrist_roll_link">
        <visual>
            <origin xyz="0 0 .03" rpy="0 0 0"/>
            <geometry>
                <box size="0.030 0.015 0.06"/>
            </geometry>
            <material name="grey"/>
        </visual>
        <visual>
            <origin xyz="0 0 0.05" rpy="0 0 0"/>
            <geometry>
                <cylinder length="0.02" radius="0.015"/>
            </geometry>
            <material name="grey"/>
        </visual>
    </link>
    <joint name="wrist_roll" type="revolute">
        <parent link="elbow_wrist_roll_link"/>
        <child link="wrist_roll_wrist_pitch_link"/>
        <origin xyz="0 0 .060028" rpy="0 0 1.57"/>
        <axis xyz="0 0 1"/>
        <limit lower="0" upper="3.14" effort="1000.0" velocity="0.5"/>
    </joint>
    <link name="wrist_roll_wrist_pitch_link">
        <visual>
            <origin xyz="0 0 .015" rpy="0 0 0"/>
            <geometry>
                <box size="0.024 0.012 0.03"/>
            </geometry>
            <material name="cyan1"/>
        </visual>
        <visual>
            <origin xyz="0 0 0.03" rpy="1.571 0 0"/>
            <geometry>
                <cylinder length="0.015" radius="0.01"/>
            </geometry>
            <material name="cyan1"/>
        </visual>
    </link>
    <joint name="wrist_pitch" type="revolute">
        <parent link="wrist_roll_wrist_pitch_link"/>
        <child link="wrist_pitch_claw_link"/>
        <origin xyz="0 0 .03017" rpy="0 -1.309 0"/>
        <axis xyz="0 1 0"/>
        <limit lower="0" upper="3.14" effort="1000.0" velocity="0.5"/>
    </joint>
    <link name="wrist_pitch_claw_link">
        <visual>
            <origin xyz="0 0 0.015" rpy="0 0 0"/>
            <geometry>
                <box size="0.012 0.03 0.03"/>
            </geometry>
            <material name="white"/>
        </visual>
    </link>
    <joint name="claw" type="fixed">
        <parent link="wrist_pitch_claw_link"/>
        <child link="claw_end_link"/>
        <origin xyz="0 0 .03017" rpy="0 0 0"/>
        <!--        <axis xyz="1 0 0"/>-->
        <!--        <limit lower="0" upper="3.14"/>-->
    </joint>
    <link name="claw_end_link">
        <visual>
            <origin xyz="0 0 .015" rpy="0 0 0"/>
            <geometry>
                <box size="0.01 0.03 0.03"/>
            </geometry>
            <material name="black"/>
        </visual>
    </link>

    <!--
    <joint name="claw_left" type="fixed">
        <parent link="wrist_pitch_claw_link"/>
        <child link="claw_left_link"/>
        <origin xyz="0 .015 0" rpy="0 0 0"/>
    </joint>
    <link name="claw_left_link">
        <visual>
            <origin xyz="0 .015 .03" rpy="0 0 0"/>
            <geometry>
                <box size="0.012 0.02 0.06"/>
            </geometry>
            <material name="white"/>
        </visual>
    </link>

    <joint name="claw_right" type="fixed">
        <parent link="wrist_pitch_claw_link"/>
        <child link="claw_right_link"/>
        <origin xyz="0 -.015 0" rpy="0 0 0"/>
    </joint>
    <link name="claw_right_link">
        <visual>
            <origin xyz="0 -.015 .03" rpy="0 0 0"/>
            <geometry>
                <box size="0.012 0.02 0.06"/>
            </geometry>
            <material name="white"/>
        </visual>
    </link>
    -->
</robot>
